{"uuid": "701af024-57c7-4963-abdc-e783c1ec4a77", "children": ["1600e683-9aef-4709-9d16-b3df406a40c0", "4b0b95a4-a590-454e-b41f-6158849005ee", "29908f09-7f4c-4bcb-afe8-1c8c0abfdd2f", "c11bb5ac-b1b6-4354-95d2-091ed92c5a1a"], "befores": [{"name": "_UnitTestCase__pytest_class_setup", "status": "broken", "statusDetails": {"message": "urllib3.exceptions.MaxRetryError: HTTPConnectionPool(host='127.0.0.1', port=4723): Max retries exceeded with url: /wd/hub/session (Caused by NewConnectionError('<urllib3.connection.HTTPConnection object at 0x000001CF4898AAC0>: Failed to establish a new connection: [WinError 10061] 由于目标计算机积极拒绝，无法连接。'))\n", "trace": "  File \"e:\\python38\\lib\\site-packages\\pluggy\\callers.py\", line 187, in _multicall\n    res = hook_impl.function(*args)\n  File \"e:\\python38\\lib\\site-packages\\_pytest\\fixtures.py\", line 1117, in pytest_fixture_setup\n    result = call_fixture_func(fixturefunc, request, kwargs)\n  File \"e:\\python38\\lib\\site-packages\\_pytest\\fixtures.py\", line 915, in call_fixture_func\n    fixture_result = next(generator)\n  File \"e:\\python38\\lib\\site-packages\\_pytest\\unittest.py\", line 131, in fixture\n    setup()\n  File \"C:\\Users\\bty\\Desktop\\ui_py_yml\\scripts\\test06_app_article.py\", line 26, in setUpClass\n    cls.driver = GetDriver.get_app_driver()\n  File \"C:\\Users\\bty\\Desktop\\ui_py_yml\\tools\\get_driver.py\", line 46, in get_app_driver\n    cls.__app_driver = appium.webdriver.Remote('http://127.0.0.1:4723/wd/hub', desired_caps)\n  File \"e:\\python38\\lib\\site-packages\\appium\\webdriver\\webdriver.py\", line 151, in __init__\n    super().__init__(\n  File \"e:\\python38\\lib\\site-packages\\selenium\\webdriver\\remote\\webdriver.py\", line 157, in __init__\n    self.start_session(capabilities, browser_profile)\n  File \"e:\\python38\\lib\\site-packages\\appium\\webdriver\\webdriver.py\", line 225, in start_session\n    response = self.execute(RemoteCommand.NEW_SESSION, parameters)\n  File \"e:\\python38\\lib\\site-packages\\selenium\\webdriver\\remote\\webdriver.py\", line 319, in execute\n    response = self.command_executor.execute(driver_command, params)\n  File \"e:\\python38\\lib\\site-packages\\selenium\\webdriver\\remote\\remote_connection.py\", line 374, in execute\n    return self._request(command_info[0], url, body=data)\n  File \"e:\\python38\\lib\\site-packages\\selenium\\webdriver\\remote\\remote_connection.py\", line 397, in _request\n    resp = self._conn.request(method, url, body=body, headers=headers)\n  File \"e:\\python38\\lib\\site-packages\\urllib3\\request.py\", line 79, in request\n    return self.request_encode_body(\n  File \"e:\\python38\\lib\\site-packages\\urllib3\\request.py\", line 171, in request_encode_body\n    return self.urlopen(method, url, **extra_kw)\n  File \"e:\\python38\\lib\\site-packages\\urllib3\\poolmanager.py\", line 336, in urlopen\n    response = conn.urlopen(method, u.request_uri, **kw)\n  File \"e:\\python38\\lib\\site-packages\\urllib3\\connectionpool.py\", line 754, in urlopen\n    return self.urlopen(\n  File \"e:\\python38\\lib\\site-packages\\urllib3\\connectionpool.py\", line 754, in urlopen\n    return self.urlopen(\n  File \"e:\\python38\\lib\\site-packages\\urllib3\\connectionpool.py\", line 754, in urlopen\n    return self.urlopen(\n  File \"e:\\python38\\lib\\site-packages\\urllib3\\connectionpool.py\", line 726, in urlopen\n    retries = retries.increment(\n  File \"e:\\python38\\lib\\site-packages\\urllib3\\util\\retry.py\", line 439, in increment\n    raise MaxRetryError(_pool, url, error or ResponseError(cause))\n"}, "start": 1600851380716, "stop": 1600851385723}, {"name": "_UnitTestCase__pytest_class_setup", "status": "broken", "statusDetails": {"message": "urllib3.exceptions.MaxRetryError: HTTPConnectionPool(host='127.0.0.1', port=4723): Max retries exceeded with url: /wd/hub/session (Caused by NewConnectionError('<urllib3.connection.HTTPConnection object at 0x000001CF489CEC10>: Failed to establish a new connection: [WinError 10061] 由于目标计算机积极拒绝，无法连接。'))\n", "trace": "  File \"e:\\python38\\lib\\site-packages\\pluggy\\callers.py\", line 187, in _multicall\n    res = hook_impl.function(*args)\n  File \"e:\\python38\\lib\\site-packages\\_pytest\\fixtures.py\", line 1117, in pytest_fixture_setup\n    result = call_fixture_func(fixturefunc, request, kwargs)\n  File \"e:\\python38\\lib\\site-packages\\_pytest\\fixtures.py\", line 915, in call_fixture_func\n    fixture_result = next(generator)\n  File \"e:\\python38\\lib\\site-packages\\_pytest\\unittest.py\", line 131, in fixture\n    setup()\n  File \"C:\\Users\\bty\\Desktop\\ui_py_yml\\scripts\\test06_app_article.py\", line 26, in setUpClass\n    cls.driver = GetDriver.get_app_driver()\n  File \"C:\\Users\\bty\\Desktop\\ui_py_yml\\tools\\get_driver.py\", line 46, in get_app_driver\n    cls.__app_driver = appium.webdriver.Remote('http://127.0.0.1:4723/wd/hub', desired_caps)\n  File \"e:\\python38\\lib\\site-packages\\appium\\webdriver\\webdriver.py\", line 151, in __init__\n    super().__init__(\n  File \"e:\\python38\\lib\\site-packages\\selenium\\webdriver\\remote\\webdriver.py\", line 157, in __init__\n    self.start_session(capabilities, browser_profile)\n  File \"e:\\python38\\lib\\site-packages\\appium\\webdriver\\webdriver.py\", line 225, in start_session\n    response = self.execute(RemoteCommand.NEW_SESSION, parameters)\n  File \"e:\\python38\\lib\\site-packages\\selenium\\webdriver\\remote\\webdriver.py\", line 319, in execute\n    response = self.command_executor.execute(driver_command, params)\n  File \"e:\\python38\\lib\\site-packages\\selenium\\webdriver\\remote\\remote_connection.py\", line 374, in execute\n    return self._request(command_info[0], url, body=data)\n  File \"e:\\python38\\lib\\site-packages\\selenium\\webdriver\\remote\\remote_connection.py\", line 397, in _request\n    resp = self._conn.request(method, url, body=body, headers=headers)\n  File \"e:\\python38\\lib\\site-packages\\urllib3\\request.py\", line 79, in request\n    return self.request_encode_body(\n  File \"e:\\python38\\lib\\site-packages\\urllib3\\request.py\", line 171, in request_encode_body\n    return self.urlopen(method, url, **extra_kw)\n  File \"e:\\python38\\lib\\site-packages\\urllib3\\poolmanager.py\", line 336, in urlopen\n    response = conn.urlopen(method, u.request_uri, **kw)\n  File \"e:\\python38\\lib\\site-packages\\urllib3\\connectionpool.py\", line 754, in urlopen\n    return self.urlopen(\n  File \"e:\\python38\\lib\\site-packages\\urllib3\\connectionpool.py\", line 754, in urlopen\n    return self.urlopen(\n  File \"e:\\python38\\lib\\site-packages\\urllib3\\connectionpool.py\", line 754, in urlopen\n    return self.urlopen(\n  File \"e:\\python38\\lib\\site-packages\\urllib3\\connectionpool.py\", line 726, in urlopen\n    retries = retries.increment(\n  File \"e:\\python38\\lib\\site-packages\\urllib3\\util\\retry.py\", line 439, in increment\n    raise MaxRetryError(_pool, url, error or ResponseError(cause))\n"}, "start": 1600851390875, "stop": 1600851395882}, {"name": "_UnitTestCase__pytest_class_setup", "status": "broken", "statusDetails": {"message": "urllib3.exceptions.MaxRetryError: HTTPConnectionPool(host='127.0.0.1', port=4723): Max retries exceeded with url: /wd/hub/session (Caused by NewConnectionError('<urllib3.connection.HTTPConnection object at 0x000001CF48973460>: Failed to establish a new connection: [WinError 10061] 由于目标计算机积极拒绝，无法连接。'))\n", "trace": "  File \"e:\\python38\\lib\\site-packages\\pluggy\\callers.py\", line 187, in _multicall\n    res = hook_impl.function(*args)\n  File \"e:\\python38\\lib\\site-packages\\_pytest\\fixtures.py\", line 1117, in pytest_fixture_setup\n    result = call_fixture_func(fixturefunc, request, kwargs)\n  File \"e:\\python38\\lib\\site-packages\\_pytest\\fixtures.py\", line 915, in call_fixture_func\n    fixture_result = next(generator)\n  File \"e:\\python38\\lib\\site-packages\\_pytest\\unittest.py\", line 131, in fixture\n    setup()\n  File \"C:\\Users\\bty\\Desktop\\ui_py_yml\\scripts\\test06_app_article.py\", line 26, in setUpClass\n    cls.driver = GetDriver.get_app_driver()\n  File \"C:\\Users\\bty\\Desktop\\ui_py_yml\\tools\\get_driver.py\", line 46, in get_app_driver\n    cls.__app_driver = appium.webdriver.Remote('http://127.0.0.1:4723/wd/hub', desired_caps)\n  File \"e:\\python38\\lib\\site-packages\\appium\\webdriver\\webdriver.py\", line 151, in __init__\n    super().__init__(\n  File \"e:\\python38\\lib\\site-packages\\selenium\\webdriver\\remote\\webdriver.py\", line 157, in __init__\n    self.start_session(capabilities, browser_profile)\n  File \"e:\\python38\\lib\\site-packages\\appium\\webdriver\\webdriver.py\", line 225, in start_session\n    response = self.execute(RemoteCommand.NEW_SESSION, parameters)\n  File \"e:\\python38\\lib\\site-packages\\selenium\\webdriver\\remote\\webdriver.py\", line 319, in execute\n    response = self.command_executor.execute(driver_command, params)\n  File \"e:\\python38\\lib\\site-packages\\selenium\\webdriver\\remote\\remote_connection.py\", line 374, in execute\n    return self._request(command_info[0], url, body=data)\n  File \"e:\\python38\\lib\\site-packages\\selenium\\webdriver\\remote\\remote_connection.py\", line 397, in _request\n    resp = self._conn.request(method, url, body=body, headers=headers)\n  File \"e:\\python38\\lib\\site-packages\\urllib3\\request.py\", line 79, in request\n    return self.request_encode_body(\n  File \"e:\\python38\\lib\\site-packages\\urllib3\\request.py\", line 171, in request_encode_body\n    return self.urlopen(method, url, **extra_kw)\n  File \"e:\\python38\\lib\\site-packages\\urllib3\\poolmanager.py\", line 336, in urlopen\n    response = conn.urlopen(method, u.request_uri, **kw)\n  File \"e:\\python38\\lib\\site-packages\\urllib3\\connectionpool.py\", line 754, in urlopen\n    return self.urlopen(\n  File \"e:\\python38\\lib\\site-packages\\urllib3\\connectionpool.py\", line 754, in urlopen\n    return self.urlopen(\n  File \"e:\\python38\\lib\\site-packages\\urllib3\\connectionpool.py\", line 754, in urlopen\n    return self.urlopen(\n  File \"e:\\python38\\lib\\site-packages\\urllib3\\connectionpool.py\", line 726, in urlopen\n    retries = retries.increment(\n  File \"e:\\python38\\lib\\site-packages\\urllib3\\util\\retry.py\", line 439, in increment\n    raise MaxRetryError(_pool, url, error or ResponseError(cause))\n"}, "start": 1600851401050, "stop": 1600851406054}], "start": 1600851401050, "stop": 1600851406361}